# Creates spawn area.
setblock ~ ~-1 ~ minecraft:oxidized_copper 
setblock ~ ~-1 ~-1 minecraft:oxidized_copper
setblock ~-1 ~-1 ~ minecraft:oxidized_copper
setblock ~ ~-1 ~1 minecraft:oxidized_copper
setblock ~1 ~-1 ~ minecraft:oxidized_copper 
setblock ~ ~-1 ~2 minecraft:oxidized_copper
setblock ~ ~-1 ~3 minecraft:oxidized_copper
setblock ~ ~-1 ~-2 minecraft:oxidized_copper
setblock ~ ~-1 ~-3 minecraft:oxidized_copper
setblock ~-2 ~-1 ~ minecraft:oxidized_copper
setblock ~-3 ~-1 ~ minecraft:oxidized_copper
setblock ~2 ~-1 ~ minecraft:oxidized_copper
setblock ~3 ~-1 ~ minecraft:oxidized_copper
setblock ~1 ~-1 ~1 minecraft:polished_diorite
setblock ~1 ~-1 ~-1 minecraft:polished_diorite
setblock ~-1 ~-1 ~1 minecraft:polished_diorite
setblock ~-1 ~-1 ~-1 minecraft:polished_diorite
setblock ~2 ~-1 ~1 minecraft:polished_diorite
setblock ~2 ~-1 ~-1 minecraft:polished_diorite
setblock ~-2 ~-1 ~-1 minecraft:polished_diorite
setblock ~-2 ~-1 ~1 minecraft:polished_diorite 
setblock ~1 ~-1 ~-2 minecraft:polished_diorite
setblock ~1 ~-1 ~2 minecraft:polished_diorite
setblock ~-1 ~-1 ~-2 minecraft:polished_diorite
setblock ~-1 ~-1 ~2 minecraft:polished_diorite
setblock ~3 ~-1 ~1 minecraft:polished_diorite
setblock ~3 ~-1 ~-1 minecraft:polished_diorite
setblock ~-3 ~-1 ~-1 minecraft:polished_diorite
setblock ~-3 ~-1 ~1 minecraft:polished_diorite 
setblock ~1 ~-1 ~-3 minecraft:polished_diorite
setblock ~1 ~-1 ~3 minecraft:polished_diorite
setblock ~-1 ~-1 ~-3 minecraft:polished_diorite
setblock ~-1 ~-1 ~3 minecraft:polished_diorite
setblock ~2 ~ ~2 minecraft:polished_diorite
setblock ~2 ~ ~-2 minecraft:polished_diorite
setblock ~-2 ~ ~2 minecraft:polished_diorite 
setblock ~-2 ~ ~-2 minecraft:polished_diorite
setblock ~2 ~1 ~2 minecraft:polished_diorite
setblock ~2 ~1 ~-2 minecraft:polished_diorite
setblock ~-2 ~1 ~2 minecraft:polished_diorite
setblock ~-2 ~1 ~-2 minecraft:polished_diorite
setblock ~3 ~-1 ~2 minecraft:calcite
setblock ~3 ~-1 ~-2 minecraft:calcite
setblock ~-3 ~-1 ~2 minecraft:calcite
setblock ~-3 ~-1 ~-2 minecraft:calcite
setblock ~2 ~-1 ~3 minecraft:calcite
setblock ~2 ~-1 ~-3 minecraft:calcite
setblock ~-2 ~-1 ~3 minecraft:calcite
setblock ~-2 ~-1 ~-3 minecraft:calcite
setblock ~3 ~-2 ~2 minecraft:calcite
setblock ~3 ~-2 ~-2 minecraft:calcite
setblock ~-3 ~-2 ~2 minecraft:calcite
setblock ~-3 ~-2 ~-2 minecraft:calcite
setblock ~2 ~-2 ~3 minecraft:calcite
setblock ~2 ~-2 ~-3 minecraft:calcite
setblock ~-2 ~-2 ~3 minecraft:calcite
setblock ~-2 ~-2 ~-3 minecraft:calcite
setblock ~3 ~-3 ~2 minecraft:calcite
setblock ~3 ~-3 ~-2 minecraft:calcite
setblock ~-3 ~-3 ~2 minecraft:calcite
setblock ~-3 ~-3 ~-2 minecraft:calcite
setblock ~2 ~-3 ~3 minecraft:calcite
setblock ~2 ~-3 ~-3 minecraft:calcite
setblock ~-2 ~-3 ~3 minecraft:calcite
setblock ~-2 ~-3 ~-3 minecraft:calcite
setblock ~3 ~-4 ~2 minecraft:calcite
setblock ~3 ~-4 ~-2 minecraft:calcite
setblock ~-3 ~-4 ~2 minecraft:calcite
setblock ~-3 ~-4 ~-2 minecraft:calcite
setblock ~2 ~-4 ~3 minecraft:calcite
setblock ~2 ~-4 ~-3 minecraft:calcite
setblock ~-2 ~-4 ~3 minecraft:calcite
setblock ~-2 ~-4 ~-3 minecraft:calcite
setblock ~-4 ~-2 ~1 minecraft:stripped_pale_oak_log  
setblock ~-4 ~-3 ~1 minecraft:stripped_pale_oak_log   
setblock ~-4 ~-4 ~1 minecraft:stripped_pale_oak_log  
setblock ~-5 ~-3 ~1 minecraft:stripped_pale_oak_log  
setblock ~-5 ~-4 ~1 minecraft:stripped_pale_oak_log  
setblock ~-6 ~-4 ~1 minecraft:stripped_pale_oak_log  
setblock ~4 ~-2 ~1 minecraft:stripped_pale_oak_log  
setblock ~4 ~-2 ~-1 minecraft:stripped_pale_oak_log    
setblock ~-4 ~-2 ~-1 minecraft:stripped_pale_oak_log  
setblock ~1 ~-2 ~4 minecraft:stripped_pale_oak_log  
setblock ~1 ~-2 ~-4 minecraft:stripped_pale_oak_log   
setblock ~-1 ~-2 ~4 minecraft:stripped_pale_oak_log  
setblock ~-1 ~-2 ~-4 minecraft:stripped_pale_oak_log  
setblock ~4 ~-3 ~1 minecraft:stripped_pale_oak_log    
setblock ~4 ~-3 ~-1 minecraft:stripped_pale_oak_log   
setblock ~-4 ~-3 ~-1 minecraft:stripped_pale_oak_log  
setblock ~1 ~-3 ~4 minecraft:stripped_pale_oak_log  
setblock ~1 ~-3 ~-4 minecraft:stripped_pale_oak_log   
setblock ~-1 ~-3 ~4 minecraft:stripped_pale_oak_log
setblock ~-1 ~-3 ~-4 minecraft:stripped_pale_oak_log
setblock ~4 ~-4 ~1 minecraft:stripped_pale_oak_log  
setblock ~4 ~-4 ~-1 minecraft:stripped_pale_oak_log
setblock ~-4 ~-4 ~-1 minecraft:stripped_pale_oak_log
setblock ~1 ~-4 ~4 minecraft:stripped_pale_oak_log
setblock ~1 ~-4 ~-4 minecraft:stripped_pale_oak_log
setblock ~-1 ~-4 ~4 minecraft:stripped_pale_oak_log
setblock ~-1 ~-4 ~-4 minecraft:stripped_pale_oak_log
setblock ~5 ~-3 ~1 minecraft:stripped_pale_oak_log 
setblock ~5 ~-3 ~-1 minecraft:stripped_pale_oak_log
setblock ~-5 ~-3 ~-1 minecraft:stripped_pale_oak_log
setblock ~1 ~-3 ~5 minecraft:stripped_pale_oak_log
setblock ~1 ~-3 ~-5 minecraft:stripped_pale_oak_log 
setblock ~-1 ~-3 ~5 minecraft:stripped_pale_oak_log
setblock ~-1 ~-3 ~-5 minecraft:stripped_pale_oak_log
setblock ~5 ~-4 ~1 minecraft:stripped_pale_oak_log 
setblock ~5 ~-4 ~-1 minecraft:stripped_pale_oak_log
setblock ~-5 ~-4 ~-1 minecraft:stripped_pale_oak_log
setblock ~1 ~-4 ~5 minecraft:stripped_pale_oak_log
setblock ~1 ~-4 ~-5 minecraft:stripped_pale_oak_log
setblock ~-1 ~-4 ~5 minecraft:stripped_pale_oak_log
setblock ~-1 ~-4 ~-5 minecraft:stripped_pale_oak_log
setblock ~6 ~-4 ~1 minecraft:stripped_pale_oak_log 
setblock ~6 ~-4 ~-1 minecraft:stripped_pale_oak_log
setblock ~-6 ~-4 ~-1 minecraft:stripped_pale_oak_log 
setblock ~1 ~-4 ~6 minecraft:stripped_pale_oak_log
setblock ~1 ~-4 ~-6 minecraft:stripped_pale_oak_log
setblock ~-1 ~-4 ~6 minecraft:stripped_pale_oak_log
setblock ~-1 ~-4 ~-6 minecraft:stripped_pale_oak_log
setblock ~4 ~-1 ~1 minecraft:oxidized_cut_copper_stairs[facing=west]
setblock ~4 ~-1 ~-1 minecraft:oxidized_cut_copper_stairs[facing=west]
setblock ~-4 ~-1 ~1 minecraft:oxidized_cut_copper_stairs[facing=east]
setblock ~-4 ~-1 ~-1 minecraft:oxidized_cut_copper_stairs[facing=east]
setblock ~1 ~-1 ~4 minecraft:oxidized_cut_copper_stairs[facing=north]
setblock ~1 ~-1 ~-4 minecraft:oxidized_cut_copper_stairs[facing=south]
setblock ~-1 ~-1 ~4 minecraft:oxidized_cut_copper_stairs[facing=north]
setblock ~-1 ~-1 ~-4 minecraft:oxidized_cut_copper_stairs[facing=south]
setblock ~5 ~-2 ~1 minecraft:oxidized_cut_copper_stairs[facing=west]
setblock ~5 ~-2 ~-1 minecraft:oxidized_cut_copper_stairs[facing=west]
setblock ~-5 ~-2 ~1 minecraft:oxidized_cut_copper_stairs[facing=east]
setblock ~-5 ~-2 ~-1 minecraft:oxidized_cut_copper_stairs[facing=east]
setblock ~1 ~-2 ~5 minecraft:oxidized_cut_copper_stairs[facing=north]
setblock ~1 ~-2 ~-5 minecraft:oxidized_cut_copper_stairs[facing=south]
setblock ~-1 ~-2 ~5 minecraft:oxidized_cut_copper_stairs[facing=north]
setblock ~-1 ~-2 ~-5 minecraft:oxidized_cut_copper_stairs[facing=south]
setblock ~6 ~-3 ~1 minecraft:oxidized_cut_copper_stairs[facing=west]
setblock ~6 ~-3 ~-1 minecraft:oxidized_cut_copper_stairs[facing=west]
setblock ~-6 ~-3 ~1 minecraft:oxidized_cut_copper_stairs[facing=east]
setblock ~-6 ~-3 ~-1 minecraft:oxidized_cut_copper_stairs[facing=east]
setblock ~1 ~-3 ~6 minecraft:oxidized_cut_copper_stairs[facing=north]
setblock ~1 ~-3 ~-6 minecraft:oxidized_cut_copper_stairs[facing=south]
setblock ~-1 ~-3 ~6 minecraft:oxidized_cut_copper_stairs[facing=north]
setblock ~-1 ~-3 ~-6 minecraft:oxidized_cut_copper_stairs[facing=south]
setblock ~7 ~-4 ~1 minecraft:oxidized_cut_copper_stairs[facing=west]
setblock ~7 ~-4 ~-1 minecraft:oxidized_cut_copper_stairs[facing=west]
setblock ~-7 ~-4 ~1 minecraft:oxidized_cut_copper_stairs[facing=east]
setblock ~1 ~-4 ~7 minecraft:oxidized_cut_copper_stairs[facing=north]
setblock ~1 ~-4 ~-7 minecraft:oxidized_cut_copper_stairs[facing=south]
setblock ~-1 ~-4 ~7 minecraft:oxidized_cut_copper_stairs[facing=north]
setblock ~-1 ~-4 ~-7 minecraft:oxidized_cut_copper_stairs[facing=south]
setblock ~-7 ~-4 ~-1 minecraft:oxidized_cut_copper_stairs[facing=east]
# Sets up treasure chest.
setblock ~ ~ ~ minecraft:chest