setblock ~ ~-1 ~ minecraft:deepslate_bricks
setblock ~1 ~-1 ~ minecraft:deepslate_bricks
setblock ~-1 ~-1 ~ minecraft:deepslate_bricks
setblock ~ ~-1 ~1 minecraft:deepslate_bricks
setblock ~ ~-1 ~-1 minecraft:deepslate_bricks
setblock ~1 ~-1 ~1 minecraft:deepslate_bricks
setblock ~1 ~-1 ~-1 minecraft:deepslate_bricks
setblock ~-1 ~-1 ~1 minecraft:deepslate_bricks
setblock ~-1 ~-1 ~-1 minecraft:deepslate_bricks
setblock ~1 ~-1 ~2 minecraft:deepslate_bricks
setblock ~1 ~-1 ~-2 minecraft:deepslate_bricks
setblock ~-1 ~-1 ~2 minecraft:deepslate_bricks
setblock ~-1 ~-1 ~-2 minecraft:deepslate_bricks
setblock ~1 ~-1 ~3 minecraft:deepslate_bricks
setblock ~1 ~-1 ~-3 minecraft:deepslate_bricks
setblock ~-1 ~-1 ~3 minecraft:deepslate_bricks
setblock ~-1 ~-1 ~-3 minecraft:deepslate_bricks
setblock ~1 ~-1 ~4 minecraft:deepslate_bricks
setblock ~1 ~-1 ~-4 minecraft:deepslate_bricks
setblock ~-1 ~-1 ~4 minecraft:deepslate_bricks
setblock ~-1 ~-1 ~-4 minecraft:deepslate_bricks
setblock ~2 ~-1 ~1 minecraft:deepslate_bricks
setblock ~2 ~-1 ~-1 minecraft:deepslate_bricks
setblock ~-2 ~-1 ~1 minecraft:deepslate_bricks
setblock ~-2 ~-1 ~-1 minecraft:deepslate_bricks
setblock ~2 ~-1 ~2 minecraft:deepslate_bricks
setblock ~2 ~-1 ~-2 minecraft:deepslate_bricks
setblock ~-2 ~-1 ~2 minecraft:deepslate_bricks
setblock ~-2 ~-1 ~-2 minecraft:deepslate_bricks
setblock ~2 ~-1 ~3 minecraft:deepslate_bricks
setblock ~2 ~-1 ~-3 minecraft:deepslate_bricks
setblock ~-2 ~-1 ~3 minecraft:deepslate_bricks
setblock ~-2 ~-1 ~-3 minecraft:deepslate_bricks
setblock ~2 ~-1 ~4 minecraft:deepslate_bricks
setblock ~2 ~-1 ~-4 minecraft:deepslate_bricks
setblock ~-2 ~-1 ~4 minecraft:deepslate_bricks
setblock ~-2 ~-1 ~-4 minecraft:deepslate_bricks
setblock ~3 ~-1 ~1 minecraft:deepslate_bricks
setblock ~3 ~-1 ~-1 minecraft:deepslate_bricks
setblock ~-3 ~-1 ~1 minecraft:deepslate_bricks
setblock ~-3 ~-1 ~-1 minecraft:deepslate_bricks
setblock ~3 ~-1 ~2 minecraft:deepslate_bricks
setblock ~3 ~-1 ~-2 minecraft:deepslate_bricks
setblock ~-3 ~-1 ~2 minecraft:deepslate_bricks
setblock ~-3 ~-1 ~-2 minecraft:deepslate_bricks
setblock ~3 ~-1 ~3 minecraft:deepslate_bricks
setblock ~3 ~-1 ~-3 minecraft:deepslate_bricks
setblock ~-3 ~-1 ~3 minecraft:deepslate_bricks
setblock ~-3 ~-1 ~-3 minecraft:deepslate_bricks
setblock ~3 ~-1 ~4 minecraft:deepslate_bricks
setblock ~3 ~-1 ~-4 minecraft:deepslate_bricks
setblock ~-3 ~-1 ~4 minecraft:deepslate_bricks
setblock ~-3 ~-1 ~-4 minecraft:deepslate_bricks
setblock ~4 ~-1 ~1 minecraft:deepslate_bricks
setblock ~4 ~-1 ~-1 minecraft:deepslate_bricks
setblock ~-4 ~-1 ~1 minecraft:deepslate_bricks
setblock ~-4 ~-1 ~-1 minecraft:deepslate_bricks
setblock ~4 ~-1 ~2 minecraft:deepslate_bricks
setblock ~4 ~-1 ~-2 minecraft:deepslate_bricks
setblock ~-4 ~-1 ~2 minecraft:deepslate_bricks
setblock ~-4 ~-1 ~-2 minecraft:deepslate_bricks
setblock ~4 ~-1 ~3 minecraft:deepslate_bricks
setblock ~4 ~-1 ~-3 minecraft:deepslate_bricks
setblock ~-4 ~-1 ~3 minecraft:deepslate_bricks
setblock ~-4 ~-1 ~-3 minecraft:deepslate_bricks
setblock ~4 ~-1 ~4 minecraft:deepslate_bricks
setblock ~4 ~-1 ~-4 minecraft:deepslate_bricks
setblock ~-4 ~-1 ~4 minecraft:deepslate_bricks
setblock ~-4 ~-1 ~-4 minecraft:deepslate_bricks
setblock ~2 ~-1 ~ minecraft:cracked_deepslate_bricks
setblock ~3 ~-1 ~ minecraft:cracked_deepslate_bricks 
setblock ~4 ~-1 ~ minecraft:cracked_deepslate_bricks
setblock ~-2 ~-1 ~ minecraft:cracked_deepslate_bricks
setblock ~-3 ~-1 ~ minecraft:cracked_deepslate_bricks
setblock ~-4 ~-1 ~ minecraft:cracked_deepslate_bricks
setblock ~ ~-1 ~2 minecraft:cracked_deepslate_bricks
setblock ~ ~-1 ~3 minecraft:cracked_deepslate_bricks
setblock ~ ~-1 ~4 minecraft:cracked_deepslate_bricks
setblock ~ ~-1 ~-2 minecraft:cracked_deepslate_bricks
setblock ~ ~-1 ~-3 minecraft:cracked_deepslate_bricks
setblock ~ ~-1 ~-4 minecraft:cracked_deepslate_bricks
setblock ~5 ~-1 ~ minecraft:mossy_stone_bricks
setblock ~-5 ~-1 ~ minecraft:mossy_stone_bricks 
setblock ~ ~-1 ~5 minecraft:mossy_stone_bricks
setblock ~ ~-1 ~-5 minecraft:mossy_stone_bricks
setblock ~5 ~-1 ~1 minecraft:mossy_stone_bricks
setblock ~5 ~-1 ~-1 minecraft:mossy_stone_bricks
setblock ~5 ~-1 ~2 minecraft:mossy_stone_bricks
setblock ~5 ~-1 ~-2 minecraft:mossy_stone_bricks
setblock ~5 ~-1 ~3 minecraft:mossy_stone_bricks
setblock ~5 ~-1 ~-3 minecraft:mossy_stone_bricks
setblock ~5 ~-1 ~4 minecraft:mossy_stone_bricks
setblock ~5 ~-1 ~-4 minecraft:mossy_stone_bricks
setblock ~5 ~-1 ~5 minecraft:mossy_stone_bricks
setblock ~5 ~-1 ~-5 minecraft:mossy_stone_bricks
setblock ~-5 ~-1 ~1 minecraft:mossy_stone_bricks
setblock ~-5 ~-1 ~-1 minecraft:mossy_stone_bricks
setblock ~-5 ~-1 ~2 minecraft:mossy_stone_bricks
setblock ~-5 ~-1 ~-2 minecraft:mossy_stone_bricks
setblock ~-5 ~-1 ~3 minecraft:mossy_stone_bricks
setblock ~-5 ~-1 ~-3 minecraft:mossy_stone_bricks
setblock ~-5 ~-1 ~4 minecraft:mossy_stone_bricks
setblock ~-5 ~-1 ~-4 minecraft:mossy_stone_bricks
setblock ~-5 ~-1 ~5 minecraft:mossy_stone_bricks
setblock ~-5 ~-1 ~-5 minecraft:mossy_stone_bricks 
setblock ~1 ~-1 ~5 minecraft:mossy_stone_bricks
setblock ~1 ~-1 ~-5 minecraft:mossy_stone_bricks
setblock ~-1 ~-1 ~5 minecraft:mossy_stone_bricks
setblock ~-1 ~-1 ~-5 minecraft:mossy_stone_bricks
setblock ~2 ~-1 ~5 minecraft:mossy_stone_bricks
setblock ~2 ~-1 ~-5 minecraft:mossy_stone_bricks
setblock ~-2 ~-1 ~5 minecraft:mossy_stone_bricks
setblock ~-2 ~-1 ~-5 minecraft:mossy_stone_bricks
setblock ~3 ~-1 ~5 minecraft:mossy_stone_bricks
setblock ~3 ~-1 ~-5 minecraft:mossy_stone_bricks
setblock ~-3 ~-1 ~5 minecraft:mossy_stone_bricks
setblock ~-3 ~-1 ~-5 minecraft:mossy_stone_bricks
setblock ~4 ~-1 ~5 minecraft:mossy_stone_bricks
setblock ~4 ~-1 ~-5 minecraft:mossy_stone_bricks
setblock ~-4 ~-1 ~5 minecraft:mossy_stone_bricks
setblock ~-4 ~-1 ~-5 minecraft:mossy_stone_bricks
setblock ~5 ~-3 ~ minecraft:mossy_stone_bricks
setblock ~-5 ~-3 ~ minecraft:mossy_stone_bricks 
setblock ~ ~-3 ~5 minecraft:mossy_stone_bricks
setblock ~ ~-3 ~-5 minecraft:mossy_stone_bricks
setblock ~5 ~-3 ~1 minecraft:mossy_stone_bricks
setblock ~5 ~-3 ~-1 minecraft:mossy_stone_bricks
setblock ~5 ~-3 ~2 minecraft:mossy_stone_bricks
setblock ~5 ~-3 ~-2 minecraft:mossy_stone_bricks
setblock ~5 ~-3 ~3 minecraft:mossy_stone_bricks
setblock ~5 ~-3 ~-3 minecraft:mossy_stone_bricks
setblock ~5 ~-3 ~4 minecraft:mossy_stone_bricks
setblock ~5 ~-3 ~-4 minecraft:mossy_stone_bricks
setblock ~5 ~-3 ~5 minecraft:mossy_stone_bricks
setblock ~5 ~-3 ~-5 minecraft:mossy_stone_bricks
setblock ~-5 ~-3 ~1 minecraft:mossy_stone_bricks
setblock ~-5 ~-3 ~-1 minecraft:mossy_stone_bricks
setblock ~-5 ~-3 ~2 minecraft:mossy_stone_bricks
setblock ~-5 ~-3 ~-2 minecraft:mossy_stone_bricks
setblock ~-5 ~-3 ~3 minecraft:mossy_stone_bricks
setblock ~-5 ~-3 ~-3 minecraft:mossy_stone_bricks
setblock ~-5 ~-3 ~4 minecraft:mossy_stone_bricks
setblock ~-5 ~-3 ~-4 minecraft:mossy_stone_bricks
setblock ~-5 ~-3 ~5 minecraft:mossy_stone_bricks
setblock ~-5 ~-3 ~-5 minecraft:mossy_stone_bricks 
setblock ~1 ~-3 ~5 minecraft:mossy_stone_bricks
setblock ~1 ~-3 ~-5 minecraft:mossy_stone_bricks
setblock ~-1 ~-3 ~5 minecraft:mossy_stone_bricks
setblock ~-1 ~-3 ~-5 minecraft:mossy_stone_bricks
setblock ~2 ~-3 ~5 minecraft:mossy_stone_bricks
setblock ~2 ~-3 ~-5 minecraft:mossy_stone_bricks
setblock ~-2 ~-3 ~5 minecraft:mossy_stone_bricks
setblock ~-2 ~-3 ~-5 minecraft:mossy_stone_bricks
setblock ~3 ~-3 ~5 minecraft:mossy_stone_bricks
setblock ~3 ~-3 ~-5 minecraft:mossy_stone_bricks
setblock ~-3 ~-3 ~5 minecraft:mossy_stone_bricks
setblock ~-3 ~-3 ~-5 minecraft:mossy_stone_bricks
setblock ~4 ~-3 ~5 minecraft:mossy_stone_bricks
setblock ~4 ~-3 ~-5 minecraft:mossy_stone_bricks
setblock ~-4 ~-3 ~5 minecraft:mossy_stone_bricks
setblock ~-4 ~-3 ~-5 minecraft:mossy_stone_bricks
setblock ~4 ~-2 ~1 minecraft:mossy_cobblestone
setblock ~4 ~-2 ~-1 minecraft:mossy_cobblestone
setblock ~-4 ~-2 ~1 minecraft:mossy_cobblestone
setblock ~-4 ~-2 ~-1 minecraft:mossy_cobblestone
setblock ~4 ~-2 ~3 minecraft:mossy_cobblestone
setblock ~4 ~-2 ~-3 minecraft:mossy_cobblestone
setblock ~-4 ~-2 ~3 minecraft:mossy_cobblestone
setblock ~-4 ~-2 ~-3 minecraft:mossy_cobblestone
setblock ~4 ~-2 ~4 minecraft:mossy_cobblestone
setblock ~4 ~-2 ~-4 minecraft:mossy_cobblestone
setblock ~-4 ~-2 ~4 minecraft:mossy_cobblestone 
setblock ~-4 ~-2 ~-4 minecraft:mossy_cobblestone
setblock ~1 ~-2 ~4 minecraft:mossy_cobblestone
setblock ~1 ~-2 ~-4 minecraft:mossy_cobblestone
setblock ~-1 ~-2 ~4 minecraft:mossy_cobblestone
setblock ~-1 ~-2 ~-4 minecraft:mossy_cobblestone
setblock ~3 ~-2 ~4 minecraft:mossy_cobblestone
setblock ~3 ~-2 ~-4 minecraft:mossy_cobblestone
setblock ~-3 ~-2 ~4 minecraft:mossy_cobblestone
setblock ~-3 ~-2 ~-4 minecraft:mossy_cobblestone
setblock ~ ~-2 ~4 minecraft:mossy_cobblestone_stairs[waterlogged=true]
setblock ~2 ~-2 ~4 minecraft:mossy_cobblestone_stairs[waterlogged=true]
setblock ~-2 ~-2 ~4 minecraft:mossy_cobblestone_stairs[waterlogged=true]
setblock ~ ~-2 ~-4 minecraft:mossy_cobblestone_stairs[waterlogged=true,facing=south]
setblock ~2 ~-2 ~-4 minecraft:mossy_cobblestone_stairs[waterlogged=true,facing=south]
setblock ~-2 ~-2 ~-4 minecraft:mossy_cobblestone_stairs[waterlogged=true,facing=south]
setblock ~4 ~-2 ~ minecraft:mossy_cobblestone_stairs[waterlogged=true,facing=west]
setblock ~4 ~-2 ~2 minecraft:mossy_cobblestone_stairs[waterlogged=true,facing=west]
setblock ~4 ~-2 ~-2 minecraft:mossy_cobblestone_stairs[waterlogged=true,facing=west]
setblock ~-4 ~-2 ~ minecraft:mossy_cobblestone_stairs[waterlogged=true,facing=east]
setblock ~-4 ~-2 ~2 minecraft:mossy_cobblestone_stairs[waterlogged=true,facing=east]
setblock ~-4 ~-2 ~-2 minecraft:mossy_cobblestone_stairs[waterlogged=true,facing=east]
setblock ~3 ~-11 ~3 minecraft:deepslate_tiles
setblock ~3 ~-11 ~-3 minecraft:deepslate_tiles
setblock ~-3 ~-11 ~3 minecraft:deepslate_tiles
setblock ~-3 ~-11 ~-3 minecraft:deepslate_tiles
setblock ~3 ~-11 ~4 minecraft:deepslate_tiles
setblock ~3 ~-11 ~-4 minecraft:deepslate_tiles
setblock ~-3 ~-11 ~4 minecraft:deepslate_tiles
setblock ~-3 ~-11 ~-4 minecraft:deepslate_tiles
setblock ~4 ~-11 ~3 minecraft:deepslate_tiles
setblock ~4 ~-11 ~-3 minecraft:deepslate_tiles
setblock ~-4 ~-11 ~3 minecraft:deepslate_tiles
setblock ~-4 ~-11 ~-3 minecraft:deepslate_tiles
setblock ~4 ~-11 ~4 minecraft:deepslate_tiles
setblock ~4 ~-11 ~-4 minecraft:deepslate_tiles
setblock ~-4 ~-11 ~4 minecraft:deepslate_tiles
setblock ~-4 ~-11 ~-4 minecraft:deepslate_tiles
setblock ~3 ~-12 ~3 minecraft:deepslate_tiles
setblock ~3 ~-12 ~-3 minecraft:deepslate_tiles
setblock ~-3 ~-12 ~3 minecraft:deepslate_tiles
setblock ~-3 ~-12 ~-3 minecraft:deepslate_tiles
setblock ~3 ~-12 ~4 minecraft:deepslate_tiles
setblock ~3 ~-12 ~-4 minecraft:deepslate_tiles
setblock ~-3 ~-12 ~4 minecraft:deepslate_tiles
setblock ~-3 ~-12 ~-4 minecraft:deepslate_tiles
setblock ~4 ~-12 ~3 minecraft:deepslate_tiles
setblock ~4 ~-12 ~-3 minecraft:deepslate_tiles
setblock ~-4 ~-12 ~3 minecraft:deepslate_tiles
setblock ~-4 ~-12 ~-3 minecraft:deepslate_tiles
setblock ~4 ~-12 ~4 minecraft:deepslate_tiles
setblock ~4 ~-12 ~-4 minecraft:deepslate_tiles
setblock ~-4 ~-12 ~4 minecraft:deepslate_tiles
setblock ~-4 ~-12 ~-4 minecraft:deepslate_tiles
setblock ~3 ~-10 ~3 minecraft:polished_andesite
setblock ~3 ~-10 ~-3 minecraft:polished_andesite
setblock ~-3 ~-10 ~3 minecraft:polished_andesite
setblock ~-3 ~-10 ~-3 minecraft:polished_andesite
setblock ~3 ~-10 ~4 minecraft:polished_andesite
setblock ~3 ~-10 ~-4 minecraft:polished_andesite
setblock ~-3 ~-10 ~4 minecraft:polished_andesite
setblock ~-3 ~-10 ~-4 minecraft:polished_andesite
setblock ~4 ~-10 ~3 minecraft:polished_andesite
setblock ~4 ~-10 ~-3 minecraft:polished_andesite
setblock ~-4 ~-10 ~3 minecraft:polished_andesite
setblock ~-4 ~-10 ~-3 minecraft:polished_andesite
setblock ~4 ~-10 ~4 minecraft:polished_andesite
setblock ~4 ~-10 ~-4 minecraft:polished_andesite
setblock ~-4 ~-10 ~4 minecraft:polished_andesite
setblock ~-4 ~-10 ~-4 minecraft:polished_andesite
setblock ~3 ~-9 ~3 minecraft:andesite 
setblock ~3 ~-9 ~-3 minecraft:polished_andesite
setblock ~-3 ~-9 ~3 minecraft:polished_andesite
setblock ~-3 ~-9 ~-3 minecraft:polished_andesite
setblock ~3 ~-9 ~4 minecraft:polished_andesite
setblock ~3 ~-9 ~-4 minecraft:andesite
setblock ~-3 ~-9 ~4 minecraft:polished_andesite
setblock ~-3 ~-9 ~-4 minecraft:polished_andesite
setblock ~4 ~-9 ~3 minecraft:polished_andesite
setblock ~4 ~-9 ~-3 minecraft:andesite
setblock ~-4 ~-9 ~3 minecraft:polished_andesite
setblock ~-4 ~-9 ~-3 minecraft:polished_andesite
setblock ~4 ~-9 ~4 minecraft:polished_andesite
setblock ~4 ~-9 ~-4 minecraft:polished_andesite
setblock ~-4 ~-9 ~4 minecraft:andesite
setblock ~-4 ~-9 ~-4 minecraft:polished_andesite
setblock ~3 ~-8 ~3 minecraft:andesite 
setblock ~3 ~-8 ~-3 minecraft:polished_andesite
setblock ~-3 ~-8 ~3 minecraft:andesite
setblock ~-3 ~-8 ~-3 minecraft:andesite
setblock ~3 ~-8 ~4 minecraft:andesite
setblock ~3 ~-8 ~-4 minecraft:polished_andesite
setblock ~-3 ~-8 ~4 minecraft:andesite
setblock ~-3 ~-8 ~-4 minecraft:andesite
setblock ~4 ~-8 ~3 minecraft:andesite
setblock ~4 ~-8 ~-3 minecraft:andesite
setblock ~-4 ~-8 ~3 minecraft:andesite
setblock ~-4 ~-8 ~-3 minecraft:andesite
setblock ~4 ~-8 ~4 minecraft:polished_andesite
setblock ~4 ~-8 ~-4 minecraft:andesite
setblock ~-4 ~-8 ~4 minecraft:andesite
setblock ~-4 ~-8 ~-4 minecraft:polished_andesite
setblock ~3 ~-7 ~3 minecraft:andesite 
setblock ~3 ~-7 ~-3 minecraft:andesite
setblock ~-3 ~-7 ~3 minecraft:andesite
setblock ~-3 ~-7 ~-3 minecraft:andesite
setblock ~3 ~-7 ~4 minecraft:cracked_stone_bricks
setblock ~3 ~-7 ~-4 minecraft:andesite
setblock ~-3 ~-7 ~4 minecraft:andesite
setblock ~-3 ~-7 ~-4 minecraft:cracked_stone_bricks
setblock ~4 ~-7 ~3 minecraft:andesite
setblock ~4 ~-7 ~-3 minecraft:andesite
setblock ~-4 ~-7 ~3 minecraft:andesite
setblock ~-4 ~-7 ~-3 minecraft:cracked_stone_bricks
setblock ~4 ~-7 ~4 minecraft:andesite
setblock ~4 ~-7 ~-4 minecraft:andesite
setblock ~-4 ~-7 ~4 minecraft:cracked_stone_bricks
setblock ~-4 ~-7 ~-4 minecraft:andesite
setblock ~3 ~-6 ~3 minecraft:cracked_stone_bricks 
setblock ~3 ~-6 ~-3 minecraft:cracked_stone_bricks
setblock ~-3 ~-6 ~3 minecraft:cracked_stone_bricks
setblock ~-3 ~-6 ~-3 minecraft:cracked_stone_bricks
setblock ~3 ~-6 ~4 minecraft:mossy_stone_bricks
setblock ~3 ~-6 ~-4 minecraft:cracked_stone_bricks
setblock ~-3 ~-6 ~4 minecraft:cracked_stone_bricks
setblock ~-3 ~-6 ~-4 minecraft:cracked_stone_bricks
setblock ~4 ~-6 ~3 minecraft:cracked_stone_bricks
setblock ~4 ~-6 ~-3 minecraft:cracked_stone_bricks
setblock ~-4 ~-6 ~3 minecraft:mossy_stone_bricks
setblock ~-4 ~-6 ~-3 minecraft:cracked_stone_bricks
setblock ~4 ~-6 ~4 minecraft:cracked_stone_bricks
setblock ~4 ~-6 ~-4 minecraft:cracked_stone_bricks
setblock ~-4 ~-6 ~4 minecraft:cracked_stone_bricks
setblock ~-4 ~-6 ~-4 minecraft:mossy_stone_bricks
setblock ~3 ~-5 ~3 minecraft:mossy_stone_bricks 
setblock ~3 ~-5 ~-3 minecraft:mossy_stone_bricks
setblock ~-3 ~-5 ~3 minecraft:mossy_stone_bricks
setblock ~-3 ~-5 ~-3 minecraft:cracked_stone_bricks
setblock ~3 ~-5 ~4 minecraft:mossy_stone_bricks
setblock ~3 ~-5 ~-4 minecraft:mossy_stone_bricks
setblock ~-3 ~-5 ~4 minecraft:mossy_stone_bricks
setblock ~-3 ~-5 ~-4 minecraft:mossy_stone_bricks
setblock ~4 ~-5 ~3 minecraft:mossy_stone_bricks
setblock ~4 ~-5 ~-3 minecraft:mossy_stone_bricks
setblock ~-4 ~-5 ~3 minecraft:cracked_stone_bricks
setblock ~-4 ~-5 ~-3 minecraft:mossy_stone_bricks
setblock ~4 ~-5 ~4 minecraft:mossy_stone_bricks
setblock ~4 ~-5 ~-4 minecraft:cracked_stone_bricks
setblock ~-4 ~-5 ~4 minecraft:mossy_stone_bricks
setblock ~-4 ~-5 ~-4 minecraft:mossy_stone_bricks
setblock ~3 ~-4 ~3 minecraft:mossy_stone_bricks 
setblock ~3 ~-4 ~-3 minecraft:mossy_stone_bricks
setblock ~-3 ~-4 ~3 minecraft:mossy_stone_bricks
setblock ~-3 ~-4 ~-3 minecraft:mossy_stone_bricks
setblock ~3 ~-4 ~4 minecraft:mossy_stone_bricks
setblock ~3 ~-4 ~-4 minecraft:mossy_stone_bricks
setblock ~-3 ~-4 ~4 minecraft:mossy_stone_bricks
setblock ~-3 ~-4 ~-4 minecraft:mossy_stone_bricks
setblock ~4 ~-4 ~3 minecraft:mossy_stone_bricks
setblock ~4 ~-4 ~-3 minecraft:mossy_stone_bricks
setblock ~-4 ~-4 ~3 minecraft:mossy_stone_bricks
setblock ~-4 ~-4 ~-3 minecraft:mossy_stone_bricks
setblock ~4 ~-4 ~4 minecraft:mossy_stone_bricks
setblock ~4 ~-4 ~-4 minecraft:mossy_stone_bricks
setblock ~-4 ~-4 ~4 minecraft:mossy_stone_bricks
setblock ~-4 ~-4 ~-4 minecraft:mossy_stone_bricks
# Sets up treasure chest.
setblock ~ ~ ~ minecraft:chest