setblock ~ ~-1 ~2 minecraft:air
setblock ~ ~ ~2 minecraft:air
setblock ~ ~-1 ~-2 minecraft:air
setblock ~ ~ ~-2 minecraft:air
setblock ~ ~26 ~-2 minecraft:water
setblock ~ ~26 ~2 minecraft:water
setblock ~ ~5 ~ minecraft:campfire
fill ~-1 ~29 ~-4 ~1 ~29 ~-4 minecraft:polished_tuff
fill ~-1 ~30 ~-4 ~-1 ~31 ~-4 minecraft:polished_tuff
setblock ~0 ~30 ~-4 minecraft:light_blue_wool
fill ~0 ~31 ~-4 ~1 ~31 ~-4 minecraft:polished_tuff
setblock ~1 ~30 ~-4 minecraft:polished_tuff
setblock ~12 ~-1 ~-4 minecraft:polished_tuff
fill ~-2 ~29 ~-3 ~-2 ~29 ~-2 minecraft:polished_tuff
fill ~-2 ~30 ~-3 ~-2 ~31 ~-3 minecraft:polished_tuff
fill ~-1 ~28 ~-3 ~1 ~28 ~-3 minecraft:polished_tuff
fill ~-1 ~32 ~-3 ~1 ~32 ~-3 minecraft:polished_tuff
fill ~2 ~29 ~-3 ~2 ~29 ~-2 minecraft:polished_tuff
fill ~2 ~30 ~-3 ~2 ~31 ~-3 minecraft:polished_tuff
fill ~-3 ~29 ~-2 ~-3 ~31 ~-1 minecraft:polished_tuff
fill ~-2 ~-1 ~-2 ~-1 ~27 ~-2 minecraft:stone
setblock ~-2 ~28 ~-2 minecraft:polished_tuff
setblock ~-2 ~32 ~-2 minecraft:polished_tuff
fill ~-1 ~33 ~-2 ~1 ~33 ~2 minecraft:polished_tuff
setblock ~0 ~27 ~-2 minecraft:polished_tuff
fill ~1 ~-1 ~-2 ~2 ~27 ~-2 minecraft:stone
setblock ~2 ~28 ~-2 minecraft:polished_tuff
setblock ~2 ~32 ~-2 minecraft:polished_tuff
fill ~3 ~29 ~-2 ~3 ~31 ~-1 minecraft:polished_tuff
fill ~-11 ~31 ~-1 ~-11 ~31 ~1 minecraft:polished_tuff_stairs["half"=top,"facing"=east]
fill ~-11 ~32 ~-1 ~-11 ~34 ~-1 minecraft:polished_tuff
fill ~-10 ~30 ~-1 ~-9 ~31 ~1 minecraft:polished_tuff
fill ~-9 ~29 ~-1 ~-9 ~29 ~1 minecraft:polished_tuff_stairs["half"=top,"facing"=east]
fill ~-9 ~32 ~-1 ~-9 ~34 ~-1 minecraft:polished_tuff
fill ~-8 ~29 ~-1 ~-4 ~29 ~-1 minecraft:polished_tuff
fill ~-8 ~31 ~-1 ~-4 ~31 ~-1 minecraft:polished_tuff
fill ~-5 ~28 ~-1 ~-3 ~28 ~-1 minecraft:polished_tuff
fill ~-5 ~32 ~-1 ~-3 ~32 ~-1 minecraft:polished_tuff
fill ~-3 ~-1 ~-1 ~-3 ~27 ~1 minecraft:stone
fill ~-2 ~-1 ~-1 ~-1 ~-1 ~1 minecraft:polished_tuff
fill ~-2 ~33 ~-1 ~-2 ~33 ~1 minecraft:polished_tuff
fill ~-1 ~4 ~-1 ~1 ~4 ~1 minecraft:polished_tuff
fill ~-1 ~34 ~-1 ~-1 ~46 ~-1 minecraft:polished_tuff
setblock ~-1 ~47 ~-1 minecraft:polished_tuff_stairs["half"=bottom,"facing"=south]
setblock ~0 ~-1 ~-1 minecraft:polished_tuff_stairs["half"=bottom,"facing"=south]
fill ~0 ~5 ~-1 ~0 ~27 ~-1 minecraft:stone
fill ~1 ~-1 ~-1 ~2 ~-1 ~1 minecraft:polished_tuff
fill ~1 ~34 ~-1 ~1 ~46 ~-1 minecraft:polished_tuff
setblock ~1 ~47 ~-1 minecraft:polished_tuff_stairs["half"=bottom,"facing"=south]
fill ~2 ~33 ~-1 ~2 ~33 ~1 minecraft:polished_tuff
fill ~3 ~-1 ~-1 ~3 ~27 ~1 minecraft:stone
fill ~3 ~28 ~-1 ~5 ~28 ~-1 minecraft:polished_tuff
fill ~3 ~32 ~-1 ~5 ~32 ~-1 minecraft:polished_tuff
fill ~4 ~29 ~-1 ~8 ~29 ~-1 minecraft:polished_tuff
fill ~4 ~31 ~-1 ~10 ~31 ~-1 minecraft:polished_tuff
fill ~9 ~29 ~-1 ~9 ~29 ~1 minecraft:polished_tuff_stairs["half"=top,"facing"=west]
fill ~9 ~30 ~-1 ~10 ~30 ~1 minecraft:polished_tuff
fill ~9 ~32 ~-1 ~9 ~34 ~-1 minecraft:polished_tuff
fill ~11 ~31 ~-1 ~11 ~31 ~1 minecraft:polished_tuff_stairs["half"=top,"facing"=west]
fill ~11 ~32 ~-1 ~11 ~34 ~-1 minecraft:polished_tuff
fill ~-10 ~32 ~0 ~-10 ~33 ~0 minecraft:polished_tuff
setblock ~-10 ~34 ~0 minecraft:light_blue_wool
fill ~-8 ~30 ~0 ~-3 ~30 ~0 minecraft:polished_tuff
fill ~-3 ~31 ~0 ~-3 ~31 ~2 minecraft:polished_tuff
fill ~-3 ~32 ~0 ~-3 ~32 ~1 minecraft:polished_tuff
fill ~-2 ~48 ~0 ~-1 ~48 ~0 minecraft:polished_tuff
setblock ~-2 ~49 ~0 minecraft:polished_tuff_stairs["half"=bottom,"facing"=east]
fill ~-1 ~47 ~0 ~1 ~47 ~0 minecraft:polished_tuff
setblock ~-1 ~49 ~0 minecraft:polished_tuff
setblock ~0 ~-1 ~0 minecraft:polished_tuff
setblock ~0 ~0 ~0 minecraft:chest["facing"="south"]
fill ~0 ~34 ~0 ~0 ~46 ~0 minecraft:polished_tuff
setblock ~0 ~48 ~0 minecraft:light_blue_wool
fill ~1 ~48 ~0 ~2 ~48 ~0 minecraft:polished_tuff
setblock ~1 ~49 ~0 minecraft:polished_tuff
setblock ~2 ~49 ~0 minecraft:polished_tuff_stairs["half"=bottom,"facing"=west]
fill ~3 ~30 ~0 ~8 ~30 ~0 minecraft:polished_tuff
fill ~3 ~31 ~0 ~3 ~31 ~2 minecraft:polished_tuff
fill ~3 ~32 ~0 ~3 ~32 ~1 minecraft:polished_tuff
fill ~9 ~31 ~0 ~10 ~31 ~1 minecraft:polished_tuff
fill ~10 ~32 ~0 ~10 ~33 ~0 minecraft:polished_tuff
setblock ~10 ~34 ~0 minecraft:light_blue_wool
fill ~-11 ~32 ~1 ~-11 ~34 ~1 minecraft:polished_tuff
fill ~-9 ~32 ~1 ~-9 ~34 ~1 minecraft:polished_tuff
fill ~-8 ~29 ~1 ~-3 ~29 ~1 minecraft:polished_tuff
fill ~-8 ~31 ~1 ~-4 ~31 ~1 minecraft:polished_tuff
fill ~-5 ~28 ~1 ~-3 ~28 ~1 minecraft:polished_tuff
fill ~-5 ~32 ~1 ~-4 ~32 ~1 minecraft:polished_tuff
fill ~-3 ~30 ~1 ~-3 ~30 ~2 minecraft:polished_tuff
fill ~-1 ~34 ~1 ~-1 ~46 ~1 minecraft:polished_tuff
setblock ~-1 ~47 ~1 minecraft:polished_tuff_stairs["half"=bottom,"facing"=north]
setblock ~0 ~-1 ~1 minecraft:polished_tuff_stairs["half"=bottom,"facing"=north]
fill ~0 ~5 ~1 ~0 ~27 ~1 minecraft:stone
fill ~1 ~34 ~1 ~1 ~46 ~1 minecraft:polished_tuff
setblock ~1 ~47 ~1 minecraft:polished_tuff_stairs["half"=bottom,"facing"=north]
fill ~3 ~28 ~1 ~5 ~29 ~1 minecraft:polished_tuff
fill ~3 ~30 ~1 ~3 ~30 ~2 minecraft:polished_tuff
fill ~4 ~31 ~1 ~8 ~31 ~1 minecraft:polished_tuff
fill ~4 ~32 ~1 ~5 ~32 ~1 minecraft:polished_tuff
fill ~6 ~29 ~1 ~8 ~29 ~1 minecraft:polished_tuff
fill ~9 ~32 ~1 ~9 ~34 ~1 minecraft:polished_tuff
fill ~11 ~32 ~1 ~11 ~34 ~1 minecraft:polished_tuff
fill ~-3 ~29 ~2 ~-2 ~29 ~2 minecraft:polished_tuff
fill ~-2 ~-1 ~2 ~-1 ~27 ~2 minecraft:stone
setblock ~-2 ~28 ~2 minecraft:polished_tuff
setblock ~-2 ~32 ~2 minecraft:polished_tuff
setblock ~0 ~27 ~2 minecraft:polished_tuff
fill ~1 ~-1 ~2 ~2 ~27 ~2 minecraft:stone
fill ~2 ~28 ~2 ~2 ~29 ~2 minecraft:polished_tuff
setblock ~2 ~32 ~2 minecraft:polished_tuff
setblock ~3 ~29 ~2 minecraft:polished_tuff
fill ~-2 ~29 ~3 ~-2 ~31 ~3 minecraft:polished_tuff
fill ~-1 ~28 ~3 ~1 ~28 ~3 minecraft:polished_tuff
fill ~-1 ~32 ~3 ~1 ~32 ~3 minecraft:polished_tuff
fill ~2 ~29 ~3 ~2 ~31 ~3 minecraft:polished_tuff
fill ~-1 ~29 ~4 ~1 ~29 ~4 minecraft:polished_tuff
fill ~-1 ~30 ~4 ~-1 ~31 ~4 minecraft:polished_tuff
setblock ~0 ~30 ~4 minecraft:light_blue_concrete_powder
fill ~0 ~31 ~4 ~1 ~31 ~4 minecraft:polished_tuff
setblock ~1 ~30 ~4 minecraft:polished_tuff
